2024-01-11 22:01:50,578 ERROR: Exception on /user/history [GET]
Traceback (most recent call last):
  File "C:\repos\amet\chastease\.venv\Lib\site-packages\flask\app.py", line 1455, in wsgi_app
    response = self.full_dispatch_request()
               ^^^^^^^^^^^^^^^^^^^^^^^^^^^^
  File "C:\repos\amet\chastease\.venv\Lib\site-packages\flask\app.py", line 869, in full_dispatch_request
    rv = self.handle_user_exception(e)
         ^^^^^^^^^^^^^^^^^^^^^^^^^^^^^
  File "C:\repos\amet\chastease\.venv\Lib\site-packages\flask\app.py", line 867, in full_dispatch_request
    rv = self.dispatch_request()
         ^^^^^^^^^^^^^^^^^^^^^^^
  File "C:\repos\amet\chastease\.venv\Lib\site-packages\flask\app.py", line 852, in dispatch_request
    return self.ensure_sync(self.view_functions[rule.endpoint])(**view_args)
           ^^^^^^^^^^^^^^^^^^^^^^^^^^^^^^^^^^^^^^^^^^^^^^^^^^^^^^^^^^^^^^^^^
  File "C:\repos\amet\chastease\.venv\Lib\site-packages\flask_login\utils.py", line 290, in decorated_view
    return current_app.ensure_sync(func)(*args, **kwargs)
           ^^^^^^^^^^^^^^^^^^^^^^^^^^^^^^^^^^^^^^^^^^^^^^
  File "C:\repos\amet\chastease\benutzer\user.py", line 246, in get_ca_lockhistory
    history = get_lock_history(last_hist_id)
              ^^^^^^^^^^^^^^^^^^^^^^^^^^^^^^
  File "C:\repos\amet\chastease\api\chaster.py", line 182, in get_lock_history
    for result in history:
TypeError: 'NoneType' object is not iterable
2024-01-11 22:06:25,807 ERROR: Exception on /user/history [GET]
Traceback (most recent call last):
  File "C:\repos\amet\chastease\.venv\Lib\site-packages\flask\app.py", line 1455, in wsgi_app
    response = self.full_dispatch_request()
               ^^^^^^^^^^^^^^^^^^^^^^^^^^^^
  File "C:\repos\amet\chastease\.venv\Lib\site-packages\flask\app.py", line 869, in full_dispatch_request
    rv = self.handle_user_exception(e)
         ^^^^^^^^^^^^^^^^^^^^^^^^^^^^^
  File "C:\repos\amet\chastease\.venv\Lib\site-packages\flask\app.py", line 867, in full_dispatch_request
    rv = self.dispatch_request()
         ^^^^^^^^^^^^^^^^^^^^^^^
  File "C:\repos\amet\chastease\.venv\Lib\site-packages\flask\app.py", line 852, in dispatch_request
    return self.ensure_sync(self.view_functions[rule.endpoint])(**view_args)
           ^^^^^^^^^^^^^^^^^^^^^^^^^^^^^^^^^^^^^^^^^^^^^^^^^^^^^^^^^^^^^^^^^
  File "C:\repos\amet\chastease\.venv\Lib\site-packages\flask_login\utils.py", line 290, in decorated_view
    return current_app.ensure_sync(func)(*args, **kwargs)
           ^^^^^^^^^^^^^^^^^^^^^^^^^^^^^^^^^^^^^^^^^^^^^^
  File "C:\repos\amet\chastease\benutzer\user.py", line 246, in get_ca_lockhistory
    history = get_lock_history(last_hist_id)
              ^^^^^^^^^^^^^^^^^^^^^^^^^^^^^^
  File "C:\repos\amet\chastease\api\chaster.py", line 180, in get_lock_history
    for result in history:
TypeError: 'NoneType' object is not iterable
2024-01-11 22:10:05,443 ERROR: Exception on /user/history [GET]
Traceback (most recent call last):
  File "C:\repos\amet\chastease\.venv\Lib\site-packages\flask\app.py", line 1455, in wsgi_app
    response = self.full_dispatch_request()
               ^^^^^^^^^^^^^^^^^^^^^^^^^^^^
  File "C:\repos\amet\chastease\.venv\Lib\site-packages\flask\app.py", line 869, in full_dispatch_request
    rv = self.handle_user_exception(e)
         ^^^^^^^^^^^^^^^^^^^^^^^^^^^^^
  File "C:\repos\amet\chastease\.venv\Lib\site-packages\flask\app.py", line 867, in full_dispatch_request
    rv = self.dispatch_request()
         ^^^^^^^^^^^^^^^^^^^^^^^
  File "C:\repos\amet\chastease\.venv\Lib\site-packages\flask\app.py", line 852, in dispatch_request
    return self.ensure_sync(self.view_functions[rule.endpoint])(**view_args)
           ^^^^^^^^^^^^^^^^^^^^^^^^^^^^^^^^^^^^^^^^^^^^^^^^^^^^^^^^^^^^^^^^^
  File "C:\repos\amet\chastease\.venv\Lib\site-packages\flask_login\utils.py", line 290, in decorated_view
    return current_app.ensure_sync(func)(*args, **kwargs)
           ^^^^^^^^^^^^^^^^^^^^^^^^^^^^^^^^^^^^^^^^^^^^^^
  File "C:\repos\amet\chastease\benutzer\user.py", line 249, in get_ca_lockhistory
    for result in history['data']:
                  ~~~~~~~^^^^^^^^
KeyError: 'data'
