2024-01-11 11:49:00,377 ERROR: Exception on /user/history [GET]
Traceback (most recent call last):
  File "C:\repos\amet\chastease\.venv\Lib\site-packages\flask\app.py", line 1455, in wsgi_app
    response = self.full_dispatch_request()
               ^^^^^^^^^^^^^^^^^^^^^^^^^^^^
  File "C:\repos\amet\chastease\.venv\Lib\site-packages\flask\app.py", line 869, in full_dispatch_request
    rv = self.handle_user_exception(e)
         ^^^^^^^^^^^^^^^^^^^^^^^^^^^^^
  File "C:\repos\amet\chastease\.venv\Lib\site-packages\flask\app.py", line 867, in full_dispatch_request
    rv = self.dispatch_request()
         ^^^^^^^^^^^^^^^^^^^^^^^
  File "C:\repos\amet\chastease\.venv\Lib\site-packages\flask\app.py", line 852, in dispatch_request
    return self.ensure_sync(self.view_functions[rule.endpoint])(**view_args)
           ^^^^^^^^^^^^^^^^^^^^^^^^^^^^^^^^^^^^^^^^^^^^^^^^^^^^^^^^^^^^^^^^^
  File "C:\repos\amet\chastease\.venv\Lib\site-packages\flask_login\utils.py", line 290, in decorated_view
    return current_app.ensure_sync(func)(*args, **kwargs)
           ^^^^^^^^^^^^^^^^^^^^^^^^^^^^^^^^^^^^^^^^^^^^^^
  File "C:\repos\amet\chastease\benutzer\user.py", line 234, in get_ca_lockhistory
    history = get_lock_history()
              ^^^^^^^^^^^^^^^^^^
  File "C:\repos\amet\chastease\api\chaster.py", line 137, in get_lock_history
    'Authorization': f'Bearer {current_user.ca_access_token}',
                               ^^^^^^^^^^^^^^^^^^^^^^^^^^^^
AttributeError: 'Benutzer' object has no attribute 'ca_access_token'
2024-01-11 12:31:15,934 ERROR: Exception on /user/history [GET]
Traceback (most recent call last):
  File "C:\repos\amet\chastease\.venv\Lib\site-packages\flask\app.py", line 1455, in wsgi_app
    response = self.full_dispatch_request()
               ^^^^^^^^^^^^^^^^^^^^^^^^^^^^
  File "C:\repos\amet\chastease\.venv\Lib\site-packages\flask\app.py", line 869, in full_dispatch_request
    rv = self.handle_user_exception(e)
         ^^^^^^^^^^^^^^^^^^^^^^^^^^^^^
  File "C:\repos\amet\chastease\.venv\Lib\site-packages\flask\app.py", line 867, in full_dispatch_request
    rv = self.dispatch_request()
         ^^^^^^^^^^^^^^^^^^^^^^^
  File "C:\repos\amet\chastease\.venv\Lib\site-packages\flask\app.py", line 852, in dispatch_request
    return self.ensure_sync(self.view_functions[rule.endpoint])(**view_args)
           ^^^^^^^^^^^^^^^^^^^^^^^^^^^^^^^^^^^^^^^^^^^^^^^^^^^^^^^^^^^^^^^^^
  File "C:\repos\amet\chastease\.venv\Lib\site-packages\flask_login\utils.py", line 290, in decorated_view
    return current_app.ensure_sync(func)(*args, **kwargs)
           ^^^^^^^^^^^^^^^^^^^^^^^^^^^^^^^^^^^^^^^^^^^^^^
  File "C:\repos\amet\chastease\benutzer\user.py", line 243, in get_ca_lockhistory
    history = get_lock_history(lastid)
              ^^^^^^^^^^^^^^^^^^^^^^^^
  File "C:\repos\amet\chastease\api\chaster.py", line 160, in get_lock_history
    current_results = response_data['data']['results']
                      ~~~~~~~~~~~~~^^^^^^^^
KeyError: 'data'
2024-01-11 12:32:14,160 ERROR: Exception on /user/history [GET]
Traceback (most recent call last):
  File "C:\repos\amet\chastease\.venv\Lib\site-packages\flask\app.py", line 1455, in wsgi_app
    response = self.full_dispatch_request()
               ^^^^^^^^^^^^^^^^^^^^^^^^^^^^
  File "C:\repos\amet\chastease\.venv\Lib\site-packages\flask\app.py", line 869, in full_dispatch_request
    rv = self.handle_user_exception(e)
         ^^^^^^^^^^^^^^^^^^^^^^^^^^^^^
  File "C:\repos\amet\chastease\.venv\Lib\site-packages\flask\app.py", line 867, in full_dispatch_request
    rv = self.dispatch_request()
         ^^^^^^^^^^^^^^^^^^^^^^^
  File "C:\repos\amet\chastease\.venv\Lib\site-packages\flask\app.py", line 852, in dispatch_request
    return self.ensure_sync(self.view_functions[rule.endpoint])(**view_args)
           ^^^^^^^^^^^^^^^^^^^^^^^^^^^^^^^^^^^^^^^^^^^^^^^^^^^^^^^^^^^^^^^^^
  File "C:\repos\amet\chastease\.venv\Lib\site-packages\flask_login\utils.py", line 290, in decorated_view
    return current_app.ensure_sync(func)(*args, **kwargs)
           ^^^^^^^^^^^^^^^^^^^^^^^^^^^^^^^^^^^^^^^^^^^^^^
  File "C:\repos\amet\chastease\benutzer\user.py", line 243, in get_ca_lockhistory
    history = get_lock_history(lastid)
              ^^^^^^^^^^^^^^^^^^^^^^^^
  File "C:\repos\amet\chastease\api\chaster.py", line 164, in get_lock_history
    if not response_data['results']['hasMore']:
           ~~~~~~~~~~~~~~~~~~~~~~~~^^^^^^^^^^^
TypeError: list indices must be integers or slices, not str
2024-01-11 12:33:25,374 ERROR: Exception on /user/history [GET]
Traceback (most recent call last):
  File "C:\repos\amet\chastease\.venv\Lib\site-packages\flask\app.py", line 1455, in wsgi_app
    response = self.full_dispatch_request()
               ^^^^^^^^^^^^^^^^^^^^^^^^^^^^
  File "C:\repos\amet\chastease\.venv\Lib\site-packages\flask\app.py", line 869, in full_dispatch_request
    rv = self.handle_user_exception(e)
         ^^^^^^^^^^^^^^^^^^^^^^^^^^^^^
  File "C:\repos\amet\chastease\.venv\Lib\site-packages\flask\app.py", line 867, in full_dispatch_request
    rv = self.dispatch_request()
         ^^^^^^^^^^^^^^^^^^^^^^^
  File "C:\repos\amet\chastease\.venv\Lib\site-packages\flask\app.py", line 852, in dispatch_request
    return self.ensure_sync(self.view_functions[rule.endpoint])(**view_args)
           ^^^^^^^^^^^^^^^^^^^^^^^^^^^^^^^^^^^^^^^^^^^^^^^^^^^^^^^^^^^^^^^^^
  File "C:\repos\amet\chastease\.venv\Lib\site-packages\flask_login\utils.py", line 290, in decorated_view
    return current_app.ensure_sync(func)(*args, **kwargs)
           ^^^^^^^^^^^^^^^^^^^^^^^^^^^^^^^^^^^^^^^^^^^^^^
  File "C:\repos\amet\chastease\benutzer\user.py", line 243, in get_ca_lockhistory
    history = get_lock_history(lastid)
              ^^^^^^^^^^^^^^^^^^^^^^^^
  File "C:\repos\amet\chastease\api\chaster.py", line 167, in get_lock_history
    if not response_data['results']['hasMore']:
           ~~~~~~~~~~~~~~~~~~~~~~~~^^^^^^^^^^^
TypeError: list indices must be integers or slices, not str
2024-01-11 12:36:09,101 ERROR: Exception on /user/history [GET]
Traceback (most recent call last):
  File "C:\repos\amet\chastease\.venv\Lib\site-packages\flask\app.py", line 1455, in wsgi_app
    response = self.full_dispatch_request()
               ^^^^^^^^^^^^^^^^^^^^^^^^^^^^
  File "C:\repos\amet\chastease\.venv\Lib\site-packages\flask\app.py", line 869, in full_dispatch_request
    rv = self.handle_user_exception(e)
         ^^^^^^^^^^^^^^^^^^^^^^^^^^^^^
  File "C:\repos\amet\chastease\.venv\Lib\site-packages\flask\app.py", line 867, in full_dispatch_request
    rv = self.dispatch_request()
         ^^^^^^^^^^^^^^^^^^^^^^^
  File "C:\repos\amet\chastease\.venv\Lib\site-packages\flask\app.py", line 852, in dispatch_request
    return self.ensure_sync(self.view_functions[rule.endpoint])(**view_args)
           ^^^^^^^^^^^^^^^^^^^^^^^^^^^^^^^^^^^^^^^^^^^^^^^^^^^^^^^^^^^^^^^^^
  File "C:\repos\amet\chastease\.venv\Lib\site-packages\flask_login\utils.py", line 290, in decorated_view
    return current_app.ensure_sync(func)(*args, **kwargs)
           ^^^^^^^^^^^^^^^^^^^^^^^^^^^^^^^^^^^^^^^^^^^^^^
  File "C:\repos\amet\chastease\benutzer\user.py", line 243, in get_ca_lockhistory
    history = get_lock_history(lastid)
              ^^^^^^^^^^^^^^^^^^^^^^^^
  File "C:\repos\amet\chastease\api\chaster.py", line 167, in get_lock_history
    if not response_data['results']['hasMore']:
           ~~~~~~~~~~~~~~~~~~~~~~~~^^^^^^^^^^^
TypeError: list indices must be integers or slices, not str
2024-01-11 12:39:41,591 ERROR: Exception on /user/history [GET]
Traceback (most recent call last):
  File "C:\repos\amet\chastease\.venv\Lib\site-packages\flask\app.py", line 1455, in wsgi_app
    response = self.full_dispatch_request()
               ^^^^^^^^^^^^^^^^^^^^^^^^^^^^
  File "C:\repos\amet\chastease\.venv\Lib\site-packages\flask\app.py", line 869, in full_dispatch_request
    rv = self.handle_user_exception(e)
         ^^^^^^^^^^^^^^^^^^^^^^^^^^^^^
  File "C:\repos\amet\chastease\.venv\Lib\site-packages\flask\app.py", line 867, in full_dispatch_request
    rv = self.dispatch_request()
         ^^^^^^^^^^^^^^^^^^^^^^^
  File "C:\repos\amet\chastease\.venv\Lib\site-packages\flask\app.py", line 852, in dispatch_request
    return self.ensure_sync(self.view_functions[rule.endpoint])(**view_args)
           ^^^^^^^^^^^^^^^^^^^^^^^^^^^^^^^^^^^^^^^^^^^^^^^^^^^^^^^^^^^^^^^^^
  File "C:\repos\amet\chastease\.venv\Lib\site-packages\flask_login\utils.py", line 290, in decorated_view
    return current_app.ensure_sync(func)(*args, **kwargs)
           ^^^^^^^^^^^^^^^^^^^^^^^^^^^^^^^^^^^^^^^^^^^^^^
  File "C:\repos\amet\chastease\benutzer\user.py", line 245, in get_ca_lockhistory
    if history['success']:
       ~~~~~~~^^^^^^^^^^^
TypeError: 'NoneType' object is not subscriptable
